Workbook
Name \a: #N/A
Name \b: #N/A
Name \c: #N/A
Name \d: #N/A
Name \e: #N/A
Name \f: #N/A
Name \g: #N/A
Name \h: #N/A
Name \i: #N/A
Name \j: #N/A
Name \k: #N/A
Name \l: #N/A
Name \M: #REF!
Name \s: #N/A
Name ___________TAB1: [1]SSlab_45°!$A$2:$H$14
Name __________Fos1: #REF!
Name __________Fos2: #REF!
Name __________LCL1: #REF!
Name __________LCL2: #REF!
Name __________LCL3: #REF!
Name __________LCL4: #REF!
Name __________LCL5: #REF!
Name __________LCL6: #REF!
Name __________LCS4: #REF!
Name __________LCS5: #REF!
Name __________LCT1: #REF!
Name __________LCT2: #REF!
Name __________LCT3: #REF!
Name __________LCT4: #REF!
Name __________LCT5: #REF!
Name __________LCT6: #REF!
Name __________LCV1: #REF!
Name __________LCV2: #REF!
Name __________LCV3: #REF!
Name __________LCV4: #REF!
Name __________LCV5: #REF!
Name __________LCV6: #REF!
Name __________TAB1: [1]SSlab_45°!$A$2:$H$14
Name __________Tcw1: #REF!
Name __________Tcw2: #REF!
Name __________Tcw3: #REF!
Name _________Fos1: #REF!
Name _________Fos2: #REF!
Name _________LCL1: #REF!
Name _________LCL2: #REF!
Name _________LCL3: #REF!
Name _________LCL4: #REF!
Name _________LCL5: #REF!
Name _________LCL6: #REF!
Name _________LCS4: #REF!
Name _________LCS5: #REF!
Name _________LCT1: #REF!
Name _________LCT2: #REF!
Name _________LCT3: #REF!
Name _________LCT4: #REF!
Name _________LCT5: #REF!
Name _________LCT6: #REF!
Name _________LCV1: #REF!
Name _________LCV2: #REF!
Name _________LCV3: #REF!

Sheet TOWER_LIST
A3: Contractor: | G3: Customer: | AM3: LOT 1: CONSTRUCTION OF 500KV JVARI - TSKALTUBO OVERHEAD LINE | BL3: Consultant:
AM4: STRUCTURE LIST
B6: INSULATOR/ HARDWARE SETS FOR CONDUCTOR | AM6: HARDWARE SETS FOR OPGW & EARTHWIRE | AU6: NOTES
B7: SS : | C7: SINGLE SUSPENSION SET | K7: 95-S : | L7: 95-S : | M7: 95-S : | N7: 95-S : | O7: 95-S : | P7: 95-S : | Q7: 95-S : | R7: 95-S : | S7: 95-S : | T7: 95-S : | U7: 95-S : | V7: 95-S : | W7: 95-S : | X7: 95-S : | Y7: 95-S : | Z7: 95-S : | AA7: 95-S : | AB7: 95-S : | AC7: 95-S : | AD7: 95-S : | AE7: 95-S : | AF7: 95-S : | AG7: 95-S : | AH7: 95-S : | AI7: 95-S : | AJ7: 95-S : | AK7: 95-S : | AL7: 95-S : | AM7: 95-S : | AN7: SUSPENSION SET FOR 95 mm2 EW/OPGW | AU7: 1- | AV7: Basic Earthing System were proposed for all Towers. The Final Earthing will determined after Soil Resistivity Tests
B8: DS : | C8: DOUBLE SUSPENSION SET | K8: 95-T : | L8: 95-T : | M8: 95-T : | N8: 95-T : | O8: 95-T : | P8: 95-T : | Q8: 95-T : | R8: 95-T : | S8: 95-T : | T8: 95-T : | U8: 95-T : | V8: 95-T : | W8: 95-T : | X8: 95-T : | Y8: 95-T : | Z8: 95-T : | AA8: 95-T : | AB8: 95-T : | AC8: 95-T : | AD8: 95-T : | AE8: 95-T : | AF8: 95-T : | AG8: 95-T : | AH8: 95-T : | AI8: 95-T : | AJ8: 95-T : | AK8: 95-T : | AL8: 95-T : | AM8: 95-T : | AN8: ANCHOR / TENSION SET FOR 95 mm2 EW/OPGW | AU8: 2- | AV8: Foundation Types will be finalized after performing the Soil Investigation Test
B9: ST : | C9: SINGLE TENSION SET | K9: 95-TSJ | L9: 95-TSJ | M9: 95-TSJ | N9: 95-TSJ | O9: 95-TSJ | P9: 95-TSJ | Q9: 95-TSJ | R9: 95-TSJ | S9: 95-TSJ | T9: 95-TSJ | U9: 95-TSJ | V9: 95-TSJ | W9: 95-TSJ | X9: 95-TSJ | Y9: 95-TSJ | Z9: 95-TSJ | AA9: 95-TSJ | AB9: 95-TSJ | AC9: 95-TSJ | AD9: 95-TSJ | AE9: 95-TSJ | AF9: 95-TSJ | AG9: 95-TSJ | AH9: 95-TSJ | AI9: 95-TSJ | AJ9: 95-TSJ | AK9: 95-TSJ | AL9: 95-TSJ | AM9: 95-TSJ | AN9: SUSPENSION SET FOR 185 mm2 EW/OPGW | AU9: 3- | AV9: The Distribution of Dampers are determined as per Damping Study for Conductor and EW
B10: 2T : | C10: DOUBLE TENSION SET | K10: 185-S : | L10: 185-S : | M10: 185-S : | N10: 185-S : | O10: 185-S : | P10: 185-S : | Q10: 185-S : | R10: 185-S : | S10: 185-S : | T10: 185-S : | U10: 185-S : | V10: 185-S : | W10: 185-S : | X10: 185-S : | Y10: 185-S : | Z10: 185-S : | AA10: 185-S : | AB10: 185-S : | AC10: 185-S : | AD10: 185-S : | AE10: 185-S : | AF10: 185-S : | AG10: 185-S : | AH10: 185-S : | AI10: 185-S : | AJ10: 185-S : | AK10: 185-S : | AL10: 185-S : | AM10: 185-S : | AN10: SUSPENSION SET FOR 185 mm2 EW/OPGW | AU10: 4- | AV10: C.W : Counter Weight
B11: 3T : | C11: TRIPLE TENSION SET | K11: 185-T : | L11: 185-T : | M11: 185-T : | N11: 185-T : | O11: 185-T : | P11: 185-T : | Q11: 185-T : | R11: 185-T : | S11: 185-T : | T11: 185-T : | U11: 185-T : | V11: 185-T : | W11: 185-T : | X11: 185-T : | Y11: 185-T : | Z11: 185-T : | AA11: 185-T : | AB11: 185-T : | AC11: 185-T : | AD11: 185-T : | AE11: 185-T : | AF11: 185-T : | AG11: 185-T : | AH11: 185-T : | AI11: 185-T : | AJ11: 185-T : | AK11: 185-T : | AL11: 185-T : | AM11: 185-T : | AN11: ANCHOR / TENSION SET FOR 185 mm2 EW/OPGW | AU11: 5- | AV11: W.S : Warning Spheres (60 cm Diameter, Red)
B12: JS : | C12: JUMPER SUSPENSION SET | K12: JB : | L12: JB : | M12: JB : | N12: JB : | O12: JB : | P12: JB : | Q12: JB : | R12: JB : | S12: JB : | T12: JB : | U12: JB : | V12: JB : | W12: JB : | X12: JB : | Y12: JB : | Z12: JB : | AA12: JB : | AB12: JB : | AC12: JB : | AD12: JB : | AE12: JB : | AF12: JB : | AG12: JB : | AH12: JB : | AI12: JB : | AJ12: JB : | AK12: JB : | AL12: JB : | AM12: JB : | AN12: JOINT BOX FOR OPGW
S13: FOUNDATION | AC13: ERECTION | AG13: STRINGING
A14: Sl.No. | B14: Towers | O14: Access Road | Q14: Soil Investigation | S14: Excavation | U14: Lean Concrete | W14: Stub Settings | Y14: Concrete | AA14: Backfilling | AC14: Ground Erection | AE14: Crane Erection | AG14: Conductor | AI14: EW | AK14: OPGW | AO14: ANGLE POINT NO. | AP14: Line Angle Degrees | AQ14: Spans | AX14: CONDUCTOR | BE14: OPGW | BI14: EARTHWIRE | BN14: Warning Spheres | BO14: GROUNDING | BS14: Towers
B15: Construction No. | C15: Tower Type | D15: Jvari Tskaltubo | H15: X COORDINATE (m) | I15: Y COORDINATE (m) | J15: Z COORDINATE (m) | K15: TODAY's PROGRESS | L15: TOMORROW'S PLAN | M15: STATUS | N15: SITE ACCESS | O15: Date of Completion | P15: Status | Q15: Date of Completion | R15: Status | S15: Date of Completion | T15: Status | U15: Date of Completion | V15: Status | W15: Date of Completion | X15: Status | Y15: Date of Completion | Z15: Status | AA15: Date of Completion | AB15: Status | AC15: Date of Completion | AD15: Status | AE15: Date of Completion | AF15: Status | AG15: Date of Completion | AH15: Status | AI15: Date of Completion | AJ15: Status | AK15: Date of Completion | AL15: Status | AM15: Cumulative Length (m) | AN15: FOUNDATION TYPE | AQ15: Actual span (m) | AR15: Wind span (m) | AS15: Weight span (m) (at Max Temperature) | AT15: Weight to Wind Span Ratio | AU15: Line Section | AV15: RULLING SPAN ( m) | AW15: SECTION LENGTH ( m) | AX15: Conductor | AY15: Insulator Strings | AZ15: Jumper String | BA15: Rigid Spacer per Jumper | BB15: Spacer damper per phase | BC15: Stock bridge damper per span per conductor (UT3) | BE15: OPGW Sets | BF15: Stock bridge damper per span per OPGW (UT2) | BH15: OPGW Joint Boxes | BI15: Earthwire Sets | BJ15: Stock bridge damper per span per EW | BL15: NOS of UT1 TYPE STOCKBRIDGE DAMPER | BM15: NOS of UT2 TYPE STOCKBRIDGE DAMPER | BO15: Type | BP15: Initial Resistance (ohm) | BQ15: Final Resistance (ohm) | BR15: Crossing | BS15: Remarks | BT15: Construction No.
D16: 1 | E16: 2 | F16: 3 | G16: 4 | BC16: Back Span | BD16: Ahead Span | BF16: Back Span | BG16: Ahead Span | BJ16: Back Span | BK16: Ahead Span
A17: 1 | B17: G1 | C17: GANTRY | D17: N.A | E17: N.A | F17: N.A | G17: N.A | H17: 301752.28 | I17: 4683922.9 | J17: 138.888 | K17: =IF(O17=TODAY(),"ACCESS ROAD",IF(Q17=TODAY(),"Soil Investigation",IF(S17=TODAY(),"Excavation",IF(U17=TODAY(),"Lean Concrete",IF(W17=TODAY(),"Stub Settings",IF(Y17=TODAY(),"Concrete",IF(AA17=TODAY(),"Backfilling",IF(AC17=TODAY(),"Ground Erection",IF(AE17=TODAY(),"Crane Erection",IF(AG17=TODAY(),"Conductor",IF(AI17=TODAY(),"EW",IF(AK17=TODAY(),"OPGW","")))))))))))) | L17: =IF(O17=TODAY()+1,"ACCESS ROAD",IF(Q17=TODAY()+1,"Soil Investigation",IF(S17=TODAY()+1,"Excavation",IF(U17=TODAY()+1,"Lean Concrete",IF(W17=TODAY()+1,"Stub Settings",IF(Y17=TODAY()+1,"Concrete",IF(AA17=TODAY()+1,"Backfilling",IF(AC17=TODAY()+1,"Ground Erection",IF(AE17=TODAY()+1,"Crane Erection",IF(AG17=TODAY()+1,"Conductor",IF(AI17=TODAY()+1,"EW",IF(AK17=TODAY()+1,"OPGW","")))))))))))) | AM17: 0 | AO17: AP0 / SS | AR17: =VLOOKUP(TOWER_LIST!B17,Spans!B:D,2,) -> 43 | AS17: =VLOOKUP(TOWER_LIST!B17,Spans!B:D,3,) -> 53 | AT17: =ROUND(AS17/AR17,2) -> 1.23 | AY17: 2T | BA17: =IF(AZ17>0,3," ") | BD17: 1 | BE17: 95-TSJ | BG17: 1 | BH17: JB | BI17: =BE17 -> 95-TSJ | BK17: 1 | BL17: 1 | BM17: 0 | BT17: G1
AQ18: 85 | AU18: 1 | AV18: 85 | AW18: 85 | AX18: =IF(AQ18<700,"400/51","500/204") -> 400/51 | BB18: 3
A19: 2 | B19: 1 | C19: B90-3 | H19: 301669.3 | I19: 4683941.3 | J19: 137.882 | K19: =IF(O19=TODAY(),"Access Road",IF(Q19=TODAY(),"Soil Investigation",IF(S19=TODAY(),"Excavation",IF(U19=TODAY(),"Lean Concrete",IF(W19=TODAY(),"Stub Settings",IF(Y19=TODAY(),"Concrete",IF(AA19=TODAY(),"Backfilling",IF(AC19=TODAY(),"Ground Erection",IF(AE19=TODAY(),"Crane Erection",IF(AG19=TODAY(),"Conductor",IF(AI19=TODAY(),"EW",IF(AK19=TODAY(),"OPGW","")))))))))))) | L19: =IF(O19=TODAY()+1,"Access Road",IF(Q19=TODAY()+1,"Soil Investigation",IF(S19=TODAY()+1,"Excavation",IF(U19=TODAY()+1,"Lean Concrete",IF(W19=TODAY()+1,"Stub Settings",IF(Y19=TODAY()+1,"Concrete",IF(AA19=TODAY()+1,"Backfilling",IF(AC19=TODAY()+1,"Ground Erection",IF(AE19=TODAY()+1,"Crane Erection",IF(AG19=TODAY()+1,"Conductor",IF(AI19=TODAY()+1,"EW",IF(AK19=TODAY()+1,"OPGW","")))))))))))) | M19: Active | O19: 45306 | P19: =IF(O19="","Not Yet",IF(O19=TODAY(),"Today Completed",IF(O19=TODAY()+1,"Tomorrow's Plan",IF(O19<TODAY(),"Completed","Not Yet")))) -> Completed | Q19: 46003 | R19: =IF(Q19="","Not Yet",IF(Q19=TODAY(),"Today Completed",IF(Q19=TODAY()+1,"Tomorrow's Plan",IF(Q19<TODAY(),"Completed","Not Yet")))) -> Completed | S19: 46117 | T19: =IF(S19="","Not Yet",IF(S19=TODAY(),"Today Completed",IF(S19=TODAY()+1,"Tomorrow's Plan",IF(S19<TODAY(),"Completed","Not Yet")))) -> Completed | V19: =IF(U19="","Not Yet",IF(U19=TODAY(),"Today Completed",IF(U19=TODAY()+1,"Tomorrow's Plan",IF(U19<TODAY(),"Completed","Not Yet")))) -> Not Yet | X19: =IF(W19="","Not Yet",IF(W19=TODAY(),"Today Completed",IF(W19=TODAY()+1,"Tomorrow's Plan",IF(W19<TODAY(),"Completed","Not Yet")))) -> Not Yet | Z19: =IF(Y19="","Not Yet",IF(Y19=TODAY(),"Today Completed",IF(Y19=TODAY()+1,"Tomorrow's Plan",IF(Y19<TODAY(),"Completed","Not Yet")))) -> Not Yet | AB19: =IF(AA19="","Not Yet",IF(AA19=TODAY(),"Today Completed",IF(AA19=TODAY()+1,"Tomorrow's Plan",IF(AA19<TODAY(),"Completed","Not Yet")))) -> Not Yet | AD19: =IF(AC19="","Not Yet",IF(AC19=TODAY(),"Today Completed",IF(AC19=TODAY()+1,"Tomorrow's Plan",IF(AC19<TODAY(),"Completed","Not Yet")))) -> Not Yet | AF19: =IF(AE19="","Not Yet",IF(AE19=TODAY(),"Today Completed",IF(AE19=TODAY()+1,"Tomorrow's Plan",IF(AE19<TODAY(),"Completed","Not Yet")))) -> Not Yet | AH19: =IF(AG19="","Not Yet",IF(AG19=TODAY(),"Today Completed",IF(AG19=TODAY()+1,"Tomorrow's Plan",IF(AG19<TODAY(),"Completed","Not Yet")))) -> Not Yet | AJ19: =IF(AI19="","Not Yet",IF(AI19=TODAY(),"Today Completed",IF(AI19=TODAY()+1,"Tomorrow's Plan",IF(AI19<TODAY(),"Completed","Not Yet")))) -> Not Yet | AL19: =IF(AK19="","Not Yet",IF(AK19=TODAY(),"Today Completed",IF(AK19=TODAY()+1,"Tomorrow's Plan",IF(AK19<TODAY(),"Completed","Not Yet")))) -> Not Yet | AM19: 85 | AN19: 5.1 | AO19: AP1 | AP19: -13.0027 | AR19: =VLOOKUP(TOWER_LIST!B19,Spans!B:D,2,) -> 183 | AS19: =VLOOKUP(TOWER_LIST!B19,Spans!B:D,3,) -> 224 | AT19: =ROUND(AS19/AR19,2) -> 1.22 | AY19: 2T-2T | AZ19: 4 | BA19: 2 | BC19: 1 | BD19: 1 | BE19: =IF(LEFT(C19,2)="BN","95-S","95-T") -> 95-T | BF19: 1 | BG19: 1 | BH19: =IF(LEFT(BE19,2)="18","JB"," " ) | BI19: =BE19 -> 95-T | BJ19: 1 | BK19: 1 | BL19: 2 | BM19: 0 | BO19: Step-1 | BT19: 1
AQ20: 280.29 | AU20: 2 | AV20: 280.29 | AW20: 280.29 | AX20: =IF(AQ20<700,"400/51","500/204") -> 400/51 | BB20: 6 | BR20: TRACK
A21: 3 | B21: 2 | C21: B30-3 | H21: 301389.02 | I21: 4683939 | J21: 134.2 | K21: =IF(O21=TODAY(),"Access Road",IF(Q21=TODAY(),"Soil Investigation",IF(S21=TODAY(),"Excavation",IF(U21=TODAY(),"Lean Concrete",IF(W21=TODAY(),"Stub Settings",IF(Y21=TODAY(),"Concrete",IF(AA21=TODAY(),"Backfilling",IF(AC21=TODAY(),"Ground Erection",IF(AE21=TODAY(),"Crane Erection",IF(AG21=TODAY(),"Conductor",IF(AI21=TODAY(),"EW",IF(AK21=TODAY(),"OPGW","")))))))))))) | L21: =IF(O21=TODAY()+1,"Access Road",IF(Q21=TODAY()+1,"Soil Investigation",IF(S21=TODAY()+1,"Excavation",IF(U21=TODAY()+1,"Lean Concrete",IF(W21=TODAY()+1,"Stub Settings",IF(Y21=TODAY()+1,"Concrete",IF(AA21=TODAY()+1,"Backfilling",IF(AC21=TODAY()+1,"Ground Erection",IF(AE21=TODAY()+1,"Crane Erection",IF(AG21=TODAY()+1,"Conductor",IF(AI21=TODAY()+1,"EW",IF(AK21=TODAY()+1,"OPGW","")))))))))))) | M21: Active | O21: 45638 | P21: =IF(O21="","Not Yet",IF(O21=TODAY(),"Today Completed",IF(O21=TODAY()+1,"Tomorrow's Plan",IF(O21<TODAY(),"Completed","Not Yet")))) -> Completed | Q21: 46003 | R21: =IF(Q21="","Not Yet",IF(Q21=TODAY(),"Today Completed",IF(Q21=TODAY()+1,"Tomorrow's Plan",IF(Q21<TODAY(),"Completed","Not Yet")))) -> Completed | S21: 46116 | T21: =IF(S21="","Not Yet",IF(S21=TODAY(),"Today Completed",IF(S21=TODAY()+1,"Tomorrow's Plan",IF(S21<TODAY(),"Completed","Not Yet")))) -> Completed | V21: =IF(U21="","Not Yet",IF(U21=TODAY(),"Today Completed",IF(U21=TODAY()+1,"Tomorrow's Plan",IF(U21<TODAY(),"Completed","Not Yet")))) -> Not Yet | X21: =IF(W21="","Not Yet",IF(W21=TODAY(),"Today Completed",IF(W21=TODAY()+1,"Tomorrow's Plan",IF(W21<TODAY(),"Completed","Not Yet")))) -> Not Yet | Z21: =IF(Y21="","Not Yet",IF(Y21=TODAY(),"Today Completed",IF(Y21=TODAY()+1,"Tomorrow's Plan",IF(Y21<TODAY(),"Completed","Not Yet")))) -> Not Yet | AB21: =IF(AA21="","Not Yet",IF(AA21=TODAY(),"Today Completed",IF(AA21=TODAY()+1,"Tomorrow's Plan",IF(AA21<TODAY(),"Completed","Not Yet")))) -> Not Yet | AD21: =IF(AC21="","Not Yet",IF(AC21=TODAY(),"Today Completed",IF(AC21=TODAY()+1,"Tomorrow's Plan",IF(AC21<TODAY(),"Completed","Not Yet")))) -> Not Yet | AF21: =IF(AE21="","Not Yet",IF(AE21=TODAY(),"Today Completed",IF(AE21=TODAY()+1,"Tomorrow's Plan",IF(AE21<TODAY(),"Completed","Not Yet")))) -> Not Yet | AH21: =IF(AG21="","Not Yet",IF(AG21=TODAY(),"Today Completed",IF(AG21=TODAY()+1,"Tomorrow's Plan",IF(AG21<TODAY(),"Completed","Not Yet")))) -> Not Yet | AJ21: =IF(AI21="","Not Yet",IF(AI21=TODAY(),"Today Completed",IF(AI21=TODAY()+1,"Tomorrow's Plan",IF(AI21<TODAY(),"Completed","Not Yet")))) -> Not Yet | AL21: =IF(AK21="","Not Yet",IF(AK21=TODAY(),"Today Completed",IF(AK21=TODAY()+1,"Tomorrow's Plan",IF(AK21<TODAY(),"Completed","Not Yet")))) -> Not Yet | AM21: 365.29 | AN21: 3 | AO21: AP2 | AP21: -23.6247 | AR21: =VLOOKUP(TOWER_LIST!B21,Spans!B:D,2,) -> 280 | AS21: =VLOOKUP(TOWER_LIST!B21,Spans!B:D,3,) -> 250 | AT21: =ROUND(AS21/AR21,2) -> 0.89 | AY21: 2T-2T | AZ21: 2 | BA21: =IF(AZ21>0,3," ") -> 3 | BC21: 1 | BD21: 1 | BE21: =IF(LEFT(C21,2)="BN","95-S","95-T") -> 95-T | BF21: 1 | BG21: 1 | BH21: =IF(LEFT(BE21,2)="18","JB"," " ) | BI21: =BE21 -> 95-T | BJ21: 1 | BK21: 1 | BL21: 2 | BM21: 0 | BO21: Step-1 | BT21: 2
AQ22: 279.71 | AU22: 3 | AV22: 291.50044 | AW22: 581.72 | AX22: =IF(AQ22<700,"400/51","500/204") -> 400/51 | BB22: 5
A23: 4 | B23: 3 | C23: BNS+6 | H23: 301133.69 | I23: 4683824.8 | J23: 129.362 | K23: =IF(O23=TODAY(),"Access Road",IF(Q23=TODAY(),"Soil Investigation",IF(S23=TODAY(),"Excavation",IF(U23=TODAY(),"Lean Concrete",IF(W23=TODAY(),"Stub Settings",IF(Y23=TODAY(),"Concrete",IF(AA23=TODAY(),"Backfilling",IF(AC23=TODAY(),"Ground Erection",IF(AE23=TODAY(),"Crane Erection",IF(AG23=TODAY(),"Conductor",IF(AI23=TODAY(),"EW",IF(AK23=TODAY(),"OPGW","")))))))))))) | L23: =IF(O23=TODAY()+1,"Access Road",IF(Q23=TODAY()+1,"Soil Investigation",IF(S23=TODAY()+1,"Excavation",IF(U23=TODAY()+1,"Lean Concrete",IF(W23=TODAY()+1,"Stub Settings",IF(Y23=TODAY()+1,"Concrete",IF(AA23=TODAY()+1,"Backfilling",IF(AC23=TODAY()+1,"Ground Erection",IF(AE23=TODAY()+1,"Crane Erection",IF(AG23=TODAY()+1,"Conductor",IF(AI23=TODAY()+1,"EW",IF(AK23=TODAY()+1,"OPGW","")))))))))))) | M23: Active | O23: 45638 | P23: =IF(O23="","Not Yet",IF(O23=TODAY(),"Today Completed",IF(O23=TODAY()+1,"Tomorrow's Plan",IF(O23<TODAY(),"Completed","Not Yet")))) -> Completed | Q23: 46003 | R23: =IF(Q23="","Not Yet",IF(Q23=TODAY(),"Today Completed",IF(Q23=TODAY()+1,"Tomorrow's Plan",IF(Q23<TODAY(),"Completed","Not Yet")))) -> Completed | T23: =IF(S23="","Not Yet",IF(S23=TODAY(),"Today Completed",IF(S23=TODAY()+1,"Tomorrow's Plan",IF(S23<TODAY(),"Completed","Not Yet")))) -> Not Yet | V23: =IF(U23="","Not Yet",IF(U23=TODAY(),"Today Completed",IF(U23=TODAY()+1,"Tomorrow's Plan",IF(U23<TODAY(),"Completed","Not Yet")))) -> Not Yet | X23: =IF(W23="","Not Yet",IF(W23=TODAY(),"Today Completed",IF(W23=TODAY()+1,"Tomorrow's Plan",IF(W23<TODAY(),"Completed","Not Yet")))) -> Not Yet | Z23: =IF(Y23="","Not Yet",IF(Y23=TODAY(),"Today Completed",IF(Y23=TODAY()+1,"Tomorrow's Plan",IF(Y23<TODAY(),"Completed","Not Yet")))) -> Not Yet | AB23: =IF(AA23="","Not Yet",IF(AA23=TODAY(),"Today Completed",IF(AA23=TODAY()+1,"Tomorrow's Plan",IF(AA23<TODAY(),"Completed","Not Yet")))) -> Not Yet | AD23: =IF(AC23="","Not Yet",IF(AC23=TODAY(),"Today Completed",IF(AC23=TODAY()+1,"Tomorrow's Plan",IF(AC23<TODAY(),"Completed","Not Yet")))) -> Not Yet | AF23: =IF(AE23="","Not Yet",IF(AE23=TODAY(),"Today Completed",IF(AE23=TODAY()+1,"Tomorrow's Plan",IF(AE23<TODAY(),"Completed","Not Yet")))) -> Not Yet | AH23: =IF(AG23="","Not Yet",IF(AG23=TODAY(),"Today Completed",IF(AG23=TODAY()+1,"Tomorrow's Plan",IF(AG23<TODAY(),"Completed","Not Yet")))) -> Not Yet | AJ23: =IF(AI23="","Not Yet",IF(AI23=TODAY(),"Today Completed",IF(AI23=TODAY()+1,"Tomorrow's Plan",IF(AI23<TODAY(),"Completed","Not Yet")))) -> Not Yet | AL23: =IF(AK23="","Not Yet",IF(AK23=TODAY(),"Today Completed",IF(AK23=TODAY()+1,"Tomorrow's Plan",IF(AK23<TODAY(),"Completed","Not Yet")))) -> Not Yet | AM23: 645 | AN23: 3 | AR23: =VLOOKUP(TOWER_LIST!B23,Spans!B:D,2,) -> 291 | AS23: =VLOOKUP(TOWER_LIST!B23,Spans!B:D,3,) -> 353 | AT23: =ROUND(AS23/AR23,2) -> 1.21 | AY23: SS | BA23: =IF(AZ23>0,3," ") | BC23: 1 | BD23: 1 | BE23: =IF(LEFT(C23,2)="BN","95-S","95-T") -> 95-S | BF23: 1 | BG23: 1 | BH23: =IF(LEFT(BE23,2)="18","JB"," " ) | BI23: =BE23 -> 95-S | BJ23: 1 | BK23: 1 | BL23: 2 | BM23: 0 | BO23: Step-1 | BT23: 3
AQ24: 302.01 | AX24: =IF(AQ24<700,"400/51","500/204") -> 400/51 | BB24: 6 | BR24: TRACK
A25: 5 | B25: 4 | C25: B60-3 | H25: 300858 | I25: 4683701.5 | J25: 126.326 | K25: =IF(O25=TODAY(),"Access Road",IF(Q25=TODAY(),"Soil Investigation",IF(S25=TODAY(),"Excavation",IF(U25=TODAY(),"Lean Concrete",IF(W25=TODAY(),"Stub Settings",IF(Y25=TODAY(),"Concrete",IF(AA25=TODAY(),"Backfilling",IF(AC25=TODAY(),"Ground Erection",IF(AE25=TODAY(),"Crane Erection",IF(AG25=TODAY(),"Conductor",IF(AI25=TODAY(),"EW",IF(AK25=TODAY(),"OPGW","")))))))))))) | L25: =IF(O25=TODAY()+1,"Access Road",IF(Q25=TODAY()+1,"Soil Investigation",IF(S25=TODAY()+1,"Excavation",IF(U25=TODAY()+1,"Lean Concrete",IF(W25=TODAY()+1,"Stub Settings",IF(Y25=TODAY()+1,"Concrete",IF(AA25=TODAY()+1,"Backfilling",IF(AC25=TODAY()+1,"Ground Erection",IF(AE25=TODAY()+1,"Crane Erection",IF(AG25=TODAY()+1,"Conductor",IF(AI25=TODAY()+1,"EW",IF(AK25=TODAY()+1,"OPGW","")))))))))))) | M25: Active | O25: 45638 | P25: =IF(O25="","Not Yet",IF(O25=TODAY(),"Today Completed",IF(O25=TODAY()+1,"Tomorrow's Plan",IF(O25<TODAY(),"Completed","Not Yet")))) -> Completed | Q25: 46003 | R25: =IF(Q25="","Not Yet",IF(Q25=TODAY(),"Today Completed",IF(Q25=TODAY()+1,"Tomorrow's Plan",IF(Q25<TODAY(),"Completed","Not Yet")))) -> Completed | T25: =IF(S25="","Not Yet",IF(S25=TODAY(),"Today Completed",IF(S25=TODAY()+1,"Tomorrow's Plan",IF(S25<TODAY(),"Completed","Not Yet")))) -> Not Yet | V25: =IF(U25="","Not Yet",IF(U25=TODAY(),"Today Completed",IF(U25=TODAY()+1,"Tomorrow's Plan",IF(U25<TODAY(),"Completed","Not Yet")))) -> Not Yet | X25: =IF(W25="","Not Yet",IF(W25=TODAY(),"Today Completed",IF(W25=TODAY()+1,"Tomorrow's Plan",IF(W25<TODAY(),"Completed","Not Yet")))) -> Not Yet | Z25: =IF(Y25="","Not Yet",IF(Y25=TODAY(),"Today Completed",IF(Y25=TODAY()+1,"Tomorrow's Plan",IF(Y25<TODAY(),"Completed","Not Yet")))) -> Not Yet | AB25: =IF(AA25="","Not Yet",IF(AA25=TODAY(),"Today Completed",IF(AA25=TODAY()+1,"Tomorrow's Plan",IF(AA25<TODAY(),"Completed","Not Yet")))) -> Not Yet | AD25: =IF(AC25="","Not Yet",IF(AC25=TODAY(),"Today Completed",IF(AC25=TODAY()+1,"Tomorrow's Plan",IF(AC25<TODAY(),"Completed","Not Yet")))) -> Not Yet | AF25: =IF(AE25="","Not Yet",IF(AE25=TODAY(),"Today Completed",IF(AE25=TODAY()+1,"Tomorrow's Plan",IF(AE25<TODAY(),"Completed","Not Yet")))) -> Not Yet | AH25: =IF(AG25="","Not Yet",IF(AG25=TODAY(),"Today Completed",IF(AG25=TODAY()+1,"Tomorrow's Plan",IF(AG25<TODAY(),"Completed","Not Yet")))) -> Not Yet | AJ25: =IF(AI25="","Not Yet",IF(AI25=TODAY(),"Today Completed",IF(AI25=TODAY()+1,"Tomorrow's Plan",IF(AI25<TODAY(),"Completed","Not Yet")))) -> Not Yet | AL25: =IF(AK25="","Not Yet",IF(AK25=TODAY(),"Today Completed",IF(AK25=TODAY()+1,"Tomorrow's Plan",IF(AK25<TODAY(),"Completed","Not Yet")))) -> Not Yet | AM25: 947.01 | AN25: 4.1 | AO25: AP3 | AP25: 50.5638 | AR25: =VLOOKUP(TOWER_LIST!B25,Spans!B:D,2,) -> 302 | AS25: =VLOOKUP(TOWER_LIST!B25,Spans!B:D,3,) -> 234 | AT25: =ROUND(AS25/AR25,2) -> 0.77 | AY25: 2T-2T | AZ25: 1 | BA25: =IF(AZ25>0,3," ") -> 3 | BC25: 1 | BD25: 1 | BE25: =IF(LEFT(C25,2)="BN","95-S","95-T") -> 95-T | BF25: 1 | BG25: 1 | BH25: =IF(LEFT(BE25,2)="18","JB"," " ) | BI25: =BE25 -> 95-T | BJ25: 1 | BK25: 1 | BL25: 2 | BM25: 0 | BO25: Step-1 | BT25: 4
AQ26: 302.56 | AU26: 4 | AV26: 322.4451 | AW26: 641.76 | AX26: =IF(AQ26<700,"400/51","500/204") -> 400/51 | BB26: 6 | BR26: ROAD
A27: 6 | B27: 5 | C27: BNS+3 | H27: 300587.15 | I27: 4683836.3 | J27: 127.391 | K27: =IF(O27=TODAY(),"Access Road",IF(Q27=TODAY(),"Soil Investigation",IF(S27=TODAY(),"Excavation",IF(U27=TODAY(),"Lean Concrete",IF(W27=TODAY(),"Stub Settings",IF(Y27=TODAY(),"Concrete",IF(AA27=TODAY(),"Backfilling",IF(AC27=TODAY(),"Ground Erection",IF(AE27=TODAY(),"Crane Erection",IF(AG27=TODAY(),"Conductor",IF(AI27=TODAY(),"EW",IF(AK27=TODAY(),"OPGW","")))))))))))) | L27: =IF(O27=TODAY()+1,"Access Road",IF(Q27=TODAY()+1,"Soil Investigation",IF(S27=TODAY()+1,"Excavation",IF(U27=TODAY()+1,"Lean Concrete",IF(W27=TODAY()+1,"Stub Settings",IF(Y27=TODAY()+1,"Concrete",IF(AA27=TODAY()+1,"Backfilling",IF(AC27=TODAY()+1,"Ground Erection",IF(AE27=TODAY()+1,"Crane Erection",IF(AG27=TODAY()+1,"Conductor",IF(AI27=TODAY()+1,"EW",IF(AK27=TODAY()+1,"OPGW","")))))))))))) | O27: 45638 | P27: =IF(O27="","Not Yet",IF(O27=TODAY(),"Today Completed",IF(O27=TODAY()+1,"Tomorrow's Plan",IF(O27<TODAY(),"Completed","Not Yet")))) -> Completed | Q27: 46003 | R27: =IF(Q27="","Not Yet",IF(Q27=TODAY(),"Today Completed",IF(Q27=TODAY()+1,"Tomorrow's Plan",IF(Q27<TODAY(),"Completed","Not Yet")))) -> Completed | T27: =IF(S27="","Not Yet",IF(S27=TODAY(),"Today Completed",IF(S27=TODAY()+1,"Tomorrow's Plan",IF(S27<TODAY(),"Completed","Not Yet")))) -> Not Yet | V27: =IF(U27="","Not Yet",IF(U27=TODAY(),"Today Completed",IF(U27=TODAY()+1,"Tomorrow's Plan",IF(U27<TODAY(),"Completed","Not Yet")))) -> Not Yet | X27: =IF(W27="","Not Yet",IF(W27=TODAY(),"Today Completed",IF(W27=TODAY()+1,"Tomorrow's Plan",IF(W27<TODAY(),"Completed","Not Yet")))) -> Not Yet | Z27: =IF(Y27="","Not Yet",IF(Y27=TODAY(),"Today Completed",IF(Y27=TODAY()+1,"Tomorrow's Plan",IF(Y27<TODAY(),"Completed","Not Yet")))) -> Not Yet | AB27: =IF(AA27="","Not Yet",IF(AA27=TODAY(),"Today Completed",IF(AA27=TODAY()+1,"Tomorrow's Plan",IF(AA27<TODAY(),"Completed","Not Yet")))) -> Not Yet | AD27: =IF(AC27="","Not Yet",IF(AC27=TODAY(),"Today Completed",IF(AC27=TODAY()+1,"Tomorrow's Plan",IF(AC27<TODAY(),"Completed","Not Yet")))) -> Not Yet | AF27: =IF(AE27="","Not Yet",IF(AE27=TODAY(),"Today Completed",IF(AE27=TODAY()+1,"Tomorrow's Plan",IF(AE27<TODAY(),"Completed","Not Yet")))) -> Not Yet | AH27: =IF(AG27="","Not Yet",IF(AG27=TODAY(),"Today Completed",IF(AG27=TODAY()+1,"Tomorrow's Plan",IF(AG27<TODAY(),"Completed","Not Yet")))) -> Not Yet | AJ27: =IF(AI27="","Not Yet",IF(AI27=TODAY(),"Today Completed",IF(AI27=TODAY()+1,"Tomorrow's Plan",IF(AI27<TODAY(),"Completed","Not Yet")))) -> Not Yet | AL27: =IF(AK27="","Not Yet",IF(AK27=TODAY(),"Today Completed",IF(AK27=TODAY()+1,"Tomorrow's Plan",IF(AK27<TODAY(),"Completed","Not Yet")))) -> Not Yet | AM27: 1249.57 | AN27: 4.1 | AR27: =VLOOKUP(TOWER_LIST!B27,Spans!B:D,2,) -> 321 | AS27: =VLOOKUP(TOWER_LIST!B27,Spans!B:D,3,) -> 361 | AT27: =ROUND(AS27/AR27,2) -> 1.12 | AY27: DS | BA27: =IF(AZ27>0,3," ") | BC27: 1 | BD27: 1 | BE27: =IF(LEFT(C27,2)="BN","95-S","95-T") -> 95-S | BF27: 1 | BG27: 1 | BH27: =IF(LEFT(BE27,2)="18","JB"," " ) | BI27: =BE27 -> 95-S | BJ27: 1 | BK27: 1 | BL27: 2 | BM27: 0 | BO27: Step-1 | BT27: 5
AQ28: 339.2 | AX28: =IF(AQ28<700,"400/51","500/204") -> 400/51 | BB28: 7
A29: 7 | B29: 6 | C29: B60+3 | H29: 300283.5 | I29: 4683987.5 | J29: 123.786 | K29: =IF(O29=TODAY(),"Access Road",IF(Q29=TODAY(),"Soil Investigation",IF(S29=TODAY(),"Excavation",IF(U29=TODAY(),"Lean Concrete",IF(W29=TODAY(),"Stub Settings",IF(Y29=TODAY(),"Concrete",IF(AA29=TODAY(),"Backfilling",IF(AC29=TODAY(),"Ground Erection",IF(AE29=TODAY(),"Crane Erection",IF(AG29=TODAY(),"Conductor",IF(AI29=TODAY(),"EW",IF(AK29=TODAY(),"OPGW","")))))))))))) | L29: =IF(O29=TODAY()+1,"Access Road",IF(Q29=TODAY()+1,"Soil Investigation",IF(S29=TODAY()+1,"Excavation",IF(U29=TODAY()+1,"Lean Concrete",IF(W29=TODAY()+1,"Stub Settings",IF(Y29=TODAY()+1,"Concrete",IF(AA29=TODAY()+1,"Backfilling",IF(AC29=TODAY()+1,"Ground Erection",IF(AE29=TODAY()+1,"Crane Erection",IF(AG29=TODAY()+1,"Conductor",IF(AI29=TODAY()+1,"EW",IF(AK29=TODAY()+1,"OPGW","")))))))))))) | O29: 45638 | P29: =IF(O29="","Not Yet",IF(O29=TODAY(),"Today Completed",IF(O29=TODAY()+1,"Tomorrow's Plan",IF(O29<TODAY(),"Completed","Not Yet")))) -> Completed | Q29: 46003 | R29: =IF(Q29="","Not Yet",IF(Q29=TODAY(),"Today Completed",IF(Q29=TODAY()+1,"Tomorrow's Plan",IF(Q29<TODAY(),"Completed","Not Yet")))) -> Completed | T29: =IF(S29="","Not Yet",IF(S29=TODAY(),"Today Completed",IF(S29=TODAY()+1,"Tomorrow's Plan",IF(S29<TODAY(),"Completed","Not Yet")))) -> Not Yet | V29: =IF(U29="","Not Yet",IF(U29=TODAY(),"Today Completed",IF(U29=TODAY()+1,"Tomorrow's Plan",IF(U29<TODAY(),"Completed","Not Yet")))) -> Not Yet | X29: =IF(W29="","Not Yet",IF(W29=TODAY(),"Today Completed",IF(W29=TODAY()+1,"Tomorrow's Plan",IF(W29<TODAY(),"Completed","Not Yet")))) -> Not Yet | Z29: =IF(Y29="","Not Yet",IF(Y29=TODAY(),"Today Completed",IF(Y29=TODAY()+1,"Tomorrow's Plan",IF(Y29<TODAY(),"Completed","Not Yet")))) -> Not Yet | AB29: =IF(AA29="","Not Yet",IF(AA29=TODAY(),"Today Completed",IF(AA29=TODAY()+1,"Tomorrow's Plan",IF(AA29<TODAY(),"Completed","Not Yet")))) -> Not Yet | AD29: =IF(AC29="","Not Yet",IF(AC29=TODAY(),"Today Completed",IF(AC29=TODAY()+1,"Tomorrow's Plan",IF(AC29<TODAY(),"Completed","Not Yet")))) -> Not Yet | AF29: =IF(AE29="","Not Yet",IF(AE29=TODAY(),"Today Completed",IF(AE29=TODAY()+1,"Tomorrow's Plan",IF(AE29<TODAY(),"Completed","Not Yet")))) -> Not Yet | AH29: =IF(AG29="","Not Yet",IF(AG29=TODAY(),"Today Completed",IF(AG29=TODAY()+1,"Tomorrow's Plan",IF(AG29<TODAY(),"Completed","Not Yet")))) -> Not Yet | AJ29: =IF(AI29="","Not Yet",IF(AI29=TODAY(),"Today Completed",IF(AI29=TODAY()+1,"Tomorrow's Plan",IF(AI29<TODAY(),"Completed","Not Yet")))) -> Not Yet | AL29: =IF(AK29="","Not Yet",IF(AK29=TODAY(),"Today Completed",IF(AK29=TODAY()+1,"Tomorrow's Plan",IF(AK29<TODAY(),"Completed","Not Yet")))) -> Not Yet | AM29: 1588.77 | AN29: 5.1 | AO29: AP4 | AP29: -51.9286 | AR29: =VLOOKUP(TOWER_LIST!B29,Spans!B:D,2,) -> 274 | AS29: =VLOOKUP(TOWER_LIST!B29,Spans!B:D,3,) -> 249 | AT29: =ROUND(AS29/AR29,2) -> 0.91 | AY29: 2T-2T | AZ29: 2 | BA29: =IF(AZ29>0,3," ") -> 3 | BC29: 1 | BD29: 1 | BE29: =IF(LEFT(C29,2)="BN","95-S","95-T") -> 95-T | BF29: 1 | BG29: 1 | BH29: =IF(LEFT(BE29,2)="18","JB"," " ) | BI29: =BE29 -> 95-T | BJ29: 1 | BK29: 1 | BL29: 2 | BM29: 0 | BO29: Step-1 | BT29: 6
AQ30: 209.33 | AU30: 5 | AV30: 209.33 | AW30: 209.33 | AX30: =IF(AQ30<700,"400/51","500/204") -> 400/51 | BB30: 4 | BR30: ROAD, RAILWAY, MV OHDL
A31: 8 | B31: 7 | C31: B90+9 | H31: 300094.5 | I31: 4683897.5 | J31: 120.878 | K31: =IF(O31=TODAY(),"Access Road",IF(Q31=TODAY(),"Soil Investigation",IF(S31=TODAY(),"Excavation",IF(U31=TODAY(),"Lean Concrete",IF(W31=TODAY(),"Stub Settings",IF(Y31=TODAY(),"Concrete",IF(AA31=TODAY(),"Backfilling",IF(AC31=TODAY(),"Ground Erection",IF(AE31=TODAY(),"Crane Erection",IF(AG31=TODAY(),"Conductor",IF(AI31=TODAY(),"EW",IF(AK31=TODAY(),"OPGW","")))))))))))) | L31: =IF(O31=TODAY()+1,"Access Road",IF(Q31=TODAY()+1,"Soil Investigation",IF(S31=TODAY()+1,"Excavation",IF(U31=TODAY()+1,"Lean Concrete",IF(W31=TODAY()+1,"Stub Settings",IF(Y31=TODAY()+1,"Concrete",IF(AA31=TODAY()+1,"Backfilling",IF(AC31=TODAY()+1,"Ground Erection",IF(AE31=TODAY()+1,"Crane Erection",IF(AG31=TODAY()+1,"Conductor",IF(AI31=TODAY()+1,"EW",IF(AK31=TODAY()+1,"OPGW","")))))))))))) | O31: 45638 | P31: =IF(O31="","Not Yet",IF(O31=TODAY(),"Today Completed",IF(O31=TODAY()+1,"Tomorrow's Plan",IF(O31<TODAY(),"Completed","Not Yet")))) -> Completed | Q31: 46003 | R31: =IF(Q31="","Not Yet",IF(Q31=TODAY(),"Today Completed",IF(Q31=TODAY()+1,"Tomorrow's Plan",IF(Q31<TODAY(),"Completed","Not Yet")))) -> Completed | S31: 46116 | T31: =IF(S31="","Not Yet",IF(S31=TODAY(),"Today Completed",IF(S31=TODAY()+1,"Tomorrow's Plan",IF(S31<TODAY(),"Completed","Not Yet")))) -> Completed | V31: =IF(U31="","Not Yet",IF(U31=TODAY(),"Today Completed",IF(U31=TODAY()+1,"Tomorrow's Plan",IF(U31<TODAY(),"Completed","Not Yet")))) -> Not Yet | X31: =IF(W31="","Not Yet",IF(W31=TODAY(),"Today Completed",IF(W31=TODAY()+1,"Tomorrow's Plan",IF(W31<TODAY(),"Completed","Not Yet")))) -> Not Yet | Z31: =IF(Y31="","Not Yet",IF(Y31=TODAY(),"Today Completed",IF(Y31=TODAY()+1,"Tomorrow's Plan",IF(Y31<TODAY(),"Completed","Not Yet")))) -> Not Yet | AB31: =IF(AA31="","Not Yet",IF(AA31=TODAY(),"Today Completed",IF(AA31=TODAY()+1,"Tomorrow's Plan",IF(AA31<TODAY(),"Completed","Not Yet")))) -> Not Yet | AD31: =IF(AC31="","Not Yet",IF(AC31=TODAY(),"Today Completed",IF(AC31=TODAY()+1,"Tomorrow's Plan",IF(AC31<TODAY(),"Completed","Not Yet")))) -> Not Yet | AF31: =IF(AE31="","Not Yet",IF(AE31=TODAY(),"Today Completed",IF(AE31=TODAY()+1,"Tomorrow's Plan",IF(AE31<TODAY(),"Completed","Not Yet")))) -> Not Yet | AH31: =IF(AG31="","Not Yet",IF(AG31=TODAY(),"Today Completed",IF(AG31=TODAY()+1,"Tomorrow's Plan",IF(AG31<TODAY(),"Completed","Not Yet")))) -> Not Yet | AJ31: =IF(AI31="","Not Yet",IF(AI31=TODAY(),"Today Completed",IF(AI31=TODAY()+1,"Tomorrow's Plan",IF(AI31<TODAY(),"Completed","Not Yet")))) -> Not Yet | AL31: =IF(AK31="","Not Yet",IF(AK31=TODAY(),"Today Completed",IF(AK31=TODAY()+1,"Tomorrow's Plan",IF(AK31<TODAY(),"Completed","Not Yet")))) -> Not Yet | AM31: 1798.1 | AN31: 3 | AO31: AP5 | AP31: 67.6282 | AR31: =VLOOKUP(TOWER_LIST!B31,Spans!B:D,2,) -> 308 | AS31: =VLOOKUP(TOWER_LIST!B31,Spans!B:D,3,) -> 343 | AT31: =ROUND(AS31/AR31,2) -> 1.11 | AY31: 2T-2T | AZ31: 2 | BA31: 2 | BC31: 1 | BD31: 1 | BE31: =IF(LEFT(C31,2)="BN","95-S","95-T") -> 95-T | BF31: 1 | BG31: 1 | BH31: JB | BI31: =BE31 -> 95-T | BJ31: 1 | BK31: 1 | BL31: 2 | BM31: 0 | BO31: Step-1 | BT31: 7
AQ32: 407.44 | AU32: 6 | AV32: 407.44 | AW32: 407.44 | AX32: =IF(AQ32<700,"400/51","500/204") -> 400/51 | BB32: 8 | BR32: ROAD, MV OHDL
A33: 9 | B33: 8 | C33: B30+3 | H33: 299792.5 | I33: 4684171 | J33: 119.573 | K33: =IF(O33=TODAY(),"Access Road",IF(Q33=TODAY(),"Soil Investigation",IF(S33=TODAY(),"Excavation",IF(U33=TODAY(),"Lean Concrete",IF(W33=TODAY(),"Stub Settings",IF(Y33=TODAY(),"Concrete",IF(AA33=TODAY(),"Backfilling",IF(AC33=TODAY(),"Ground Erection",IF(AE33=TODAY(),"Crane Erection",IF(AG33=TODAY(),"Conductor",IF(AI33=TODAY(),"EW",IF(AK33=TODAY(),"OPGW","")))))))))))) | L33: =IF(O33=TODAY()+1,"Access Road",IF(Q33=TODAY()+1,"Soil Investigation",IF(S33=TODAY()+1,"Excavation",IF(U33=TODAY()+1,"Lean Concrete",IF(W33=TODAY()+1,"Stub Settings",IF(Y33=TODAY()+1,"Concrete",IF(AA33=TODAY()+1,"Backfilling",IF(AC33=TODAY()+1,"Ground Erection",IF(AE33=TODAY()+1,"Crane Erection",IF(AG33=TODAY()+1,"Conductor",IF(AI33=TODAY()+1,"EW",IF(AK33=TODAY()+1,"OPGW","")))))))))))) | O33: 45638 | P33: =IF(O33="","Not Yet",IF(O33=TODAY(),"Today Completed",IF(O33=TODAY()+1,"Tomorrow's Plan",IF(O33<TODAY(),"Completed","Not Yet")))) -> Completed | Q33: 46003 | R33: =IF(Q33="","Not Yet",IF(Q33=TODAY(),"Today Completed",IF(Q33=TODAY()+1,"Tomorrow's Plan",IF(Q33<TODAY(),"Completed","Not Yet")))) -> Completed | S33: 15/12/2025 | T33: =IF(S33="","Not Yet",IF(S33=TODAY(),"Today Completed",IF(S33=TODAY()+1,"Tomorrow's Plan",IF(S33<TODAY(),"Completed","Not Yet")))) -> Not Yet | U33: 15/12/2025 | V33: =IF(U33="","Not Yet",IF(U33=TODAY(),"Today Completed",IF(U33=TODAY()+1,"Tomorrow's Plan",IF(U33<TODAY(),"Completed","Not Yet")))) -> Not Yet | W33: 15/12/2025 | X33: =IF(W33="","Not Yet",IF(W33=TODAY(),"Today Completed",IF(W33=TODAY()+1,"Tomorrow's Plan",IF(W33<TODAY(),"Completed","Not Yet")))) -> Not Yet | Y33: 15/12/2025 | Z33: =IF(Y33="","Not Yet",IF(Y33=TODAY(),"Today Completed",IF(Y33=TODAY()+1,"Tomorrow's Plan",IF(Y33<TODAY(),"Completed","Not Yet")))) -> Not Yet | AB33: =IF(AA33="","Not Yet",IF(AA33=TODAY(),"Today Completed",IF(AA33=TODAY()+1,"Tomorrow's Plan",IF(AA33<TODAY(),"Completed","Not Yet")))) -> Not Yet | AD33: =IF(AC33="","Not Yet",IF(AC33=TODAY(),"Today Completed",IF(AC33=TODAY()+1,"Tomorrow's Plan",IF(AC33<TODAY(),"Completed","Not Yet")))) -> Not Yet | AF33: =IF(AE33="","Not Yet",IF(AE33=TODAY(),"Today Completed",IF(AE33=TODAY()+1,"Tomorrow's Plan",IF(AE33<TODAY(),"Completed","Not Yet")))) -> Not Yet | AH33: =IF(AG33="","Not Yet",IF(AG33=TODAY(),"Today Completed",IF(AG33=TODAY()+1,"Tomorrow's Plan",IF(AG33<TODAY(),"Completed","Not Yet")))) -> Not Yet | AJ33: =IF(AI33="","Not Yet",IF(AI33=TODAY(),"Today Completed",IF(AI33=TODAY()+1,"Tomorrow's Plan",IF(AI33<TODAY(),"Completed","Not Yet")))) -> Not Yet | AL33: =IF(AK33="","Not Yet",IF(AK33=TODAY(),"Today Completed",IF(AK33=TODAY()+1,"Tomorrow's Plan",IF(AK33<TODAY(),"Completed","Not Yet")))) -> Not Yet | AM33: 2205.54 | AN33: 5.1 | AO33: AP6 | AP33: -17.7222 | AR33: =VLOOKUP(TOWER_LIST!B33,Spans!B:D,2,) -> 398 | AS33: =VLOOKUP(TOWER_LIST!B33,Spans!B:D,3,) -> 378 | AT33: =ROUND(AS33/AR33,2) -> 0.95 | AY33: 2T-2T | AZ33: 2 | BA33: =IF(AZ33>0,3," ") -> 3 | BC33: 1 | BD33: 1 | BE33: =IF(LEFT(C33,2)="BN","95-S","95-T") -> 95-T | BF33: 1 | BG33: 1 | BH33: =IF(LEFT(BE33,2)="18","JB"," " ) | BI33: =BE33 -> 95-T | BJ33: 1 | BK33: 1 | BL33: 2 | BM33: 0 | BO33: Step-1 | BT33: 8
AQ34: 389.46 | AU34: 7 | AV34: 375.59751 | AW34: 749.46 | AX34: =IF(AQ34<700,"400/51","500/204") -> 400/51 | BB34: 8
A35: 10 | B35: 9 | C35: BNS+6 | H35: 299437.95 | I35: 4684332.2 | J35: 117.014 | K35: =IF(O35=TODAY(),"Access Road",IF(Q35=TODAY(),"Soil Investigation",IF(S35=TODAY(),"Excavation",IF(U35=TODAY(),"Lean Concrete",IF(W35=TODAY(),"Stub Settings",IF(Y35=TODAY(),"Concrete",IF(AA35=TODAY(),"Backfilling",IF(AC35=TODAY(),"Ground Erection",IF(AE35=TODAY(),"Crane Erection",IF(AG35=TODAY(),"Conductor",IF(AI35=TODAY(),"EW",IF(AK35=TODAY(),"OPGW","")))))))))))) | L35: =IF(O35=TODAY()+1,"Access Road",IF(Q35=TODAY()+1,"Soil Investigation",IF(S35=TODAY()+1,"Excavation",IF(U35=TODAY()+1,"Lean Concrete",IF(W35=TODAY()+1,"Stub Settings",IF(Y35=TODAY()+1,"Concrete",IF(AA35=TODAY()+1,"Backfilling",IF(AC35=TODAY()+1,"Ground Erection",IF(AE35=TODAY()+1,"Crane Erection",IF(AG35=TODAY()+1,"Conductor",IF(AI35=TODAY()+1,"EW",IF(AK35=TODAY()+1,"OPGW","")))))))))))) | O35: 45638 | P35: =IF(O35="","Not Yet",IF(O35=TODAY(),"Today Completed",IF(O35=TODAY()+1,"Tomorrow's Plan",IF(O35<TODAY(),"Completed","Not Yet")))) -> Completed | Q35: 46003 | R35: =IF(Q35="","Not Yet",IF(Q35=TODAY(),"Today Completed",IF(Q35=TODAY()+1,"Tomorrow's Plan",IF(Q35<TODAY(),"Completed","Not Yet")))) -> Completed | S35: 15/12/2025 | T35: =IF(S35="","Not Yet",IF(S35=TODAY(),"Today Completed",IF(S35=TODAY()+1,"Tomorrow's Plan",IF(S35<TODAY(),"Completed","Not Yet")))) -> Not Yet | U35: 15/12/2025 | V35: =IF(U35="","Not Yet",IF(U35=TODAY(),"Today Completed",IF(U35=TODAY()+1,"Tomorrow's Plan",IF(U35<TODAY(),"Completed","Not Yet")))) -> Not Yet | W35: 15/12/2025 | X35: =IF(W35="","Not Yet",IF(W35=TODAY(),"Today Completed",IF(W35=TODAY()+1,"Tomorrow's Plan",IF(W35<TODAY(),"Completed","Not Yet")))) -> Not Yet | Y35: 15/12/2025 | Z35: =IF(Y35="","Not Yet",IF(Y35=TODAY(),"Today Completed",IF(Y35=TODAY()+1,"Tomorrow's Plan",IF(Y35<TODAY(),"Completed","Not Yet")))) -> Not Yet | AB35: =IF(AA35="","Not Yet",IF(AA35=TODAY(),"Today Completed",IF(AA35=TODAY()+1,"Tomorrow's Plan",IF(AA35<TODAY(),"Completed","Not Yet")))) -> Not Yet | AD35: =IF(AC35="","Not Yet",IF(AC35=TODAY(),"Today Completed",IF(AC35=TODAY()+1,"Tomorrow's Plan",IF(AC35<TODAY(),"Completed","Not Yet")))) -> Not Yet | AF35: =IF(AE35="","Not Yet",IF(AE35=TODAY(),"Today Completed",IF(AE35=TODAY()+1,"Tomorrow's Plan",IF(AE35<TODAY(),"Completed","Not Yet")))) -> Not Yet | AH35: =IF(AG35="","Not Yet",IF(AG35=TODAY(),"Today Completed",IF(AG35=TODAY()+1,"Tomorrow's Plan",IF(AG35<TODAY(),"Completed","Not Yet")))) -> Not Yet | AJ35: =IF(AI35="","Not Yet",IF(AI35=TODAY(),"Today Completed",IF(AI35=TODAY()+1,"Tomorrow's Plan",IF(AI35<TODAY(),"Completed","Not Yet")))) -> Not Yet | AL35: =IF(AK35="","Not Yet",IF(AK35=TODAY(),"Today Completed",IF(AK35=TODAY()+1,"Tomorrow's Plan",IF(AK35<TODAY(),"Completed","Not Yet")))) -> Not Yet | AM35: 2595 | AN35: 3 | AR35: =VLOOKUP(TOWER_LIST!B35,Spans!B:D,2,) -> 375 | AS35: =VLOOKUP(TOWER_LIST!B35,Spans!B:D,3,) -> 414 | AT35: =ROUND(AS35/AR35,2) -> 1.1 | AY35: SS | BA35: =IF(AZ35>0,3," ") | BC35: 1 | BD35: 1 | BE35: =IF(LEFT(C35,2)="BN","95-S","95-T") -> 95-S | BF35: 1 | BG35: 1 | BH35: =IF(LEFT(BE35,2)="18","JB"," " ) | BI35: =BE35 -> 95-S | BJ35: 1 | BK35: 1 | BL35: 2 | BM35: 0 | BO35: Step-1 | BT35: 9
AQ36: 360 | AX36: =IF(AQ36<700,"400/51","500/204") -> 400/51 | BB36: 7
A37: 11 | B37: 10 | C37: B30-3 | H37: 299110.21 | I37: 4684481.1 | J37: 115.154 | K37: =IF(O37=TODAY(),"Access Road",IF(Q37=TODAY(),"Soil Investigation",IF(S37=TODAY(),"Excavation",IF(U37=TODAY(),"Lean Concrete",IF(W37=TODAY(),"Stub Settings",IF(Y37=TODAY(),"Concrete",IF(AA37=TODAY(),"Backfilling",IF(AC37=TODAY(),"Ground Erection",IF(AE37=TODAY(),"Crane Erection",IF(AG37=TODAY(),"Conductor",IF(AI37=TODAY(),"EW",IF(AK37=TODAY(),"OPGW","")))))))))))) | L37: =IF(O37=TODAY()+1,"Access Road",IF(Q37=TODAY()+1,"Soil Investigation",IF(S37=TODAY()+1,"Excavation",IF(U37=TODAY()+1,"Lean Concrete",IF(W37=TODAY()+1,"Stub Settings",IF(Y37=TODAY()+1,"Concrete",IF(AA37=TODAY()+1,"Backfilling",IF(AC37=TODAY()+1,"Ground Erection",IF(AE37=TODAY()+1,"Crane Erection",IF(AG37=TODAY()+1,"Conductor",IF(AI37=TODAY()+1,"EW",IF(AK37=TODAY()+1,"OPGW","")))))))))))) | O37: 45638 | P37: =IF(O37="","Not Yet",IF(O37=TODAY(),"Today Completed",IF(O37=TODAY()+1,"Tomorrow's Plan",IF(O37<TODAY(),"Completed","Not Yet")))) -> Completed | Q37: 46003 | R37: =IF(Q37="","Not Yet",IF(Q37=TODAY(),"Today Completed",IF(Q37=TODAY()+1,"Tomorrow's Plan",IF(Q37<TODAY(),"Completed","Not Yet")))) -> Completed | S37: 30/03/2026 | T37: =IF(S37="","Not Yet",IF(S37=TODAY(),"Today Completed",IF(S37=TODAY()+1,"Tomorrow's Plan",IF(S37<TODAY(),"Completed","Not Yet")))) -> Not Yet | U37: 30/03/2026 | V37: =IF(U37="","Not Yet",IF(U37=TODAY(),"Today Completed",IF(U37=TODAY()+1,"Tomorrow's Plan",IF(U37<TODAY(),"Completed","Not Yet")))) -> Not Yet | W37: 30/03/2026 | X37: =IF(W37="","Not Yet",IF(W37=TODAY(),"Today Completed",IF(W37=TODAY()+1,"Tomorrow's Plan",IF(W37<TODAY(),"Completed","Not Yet")))) -> Not Yet | Y37: 30/03/2026 | Z37: =IF(Y37="","Not Yet",IF(Y37=TODAY(),"Today Completed",IF(Y37=TODAY()+1,"Tomorrow's Plan",IF(Y37<TODAY(),"Completed","Not Yet")))) -> Not Yet | AB37: =IF(AA37="","Not Yet",IF(AA37=TODAY(),"Today Completed",IF(AA37=TODAY()+1,"Tomorrow's Plan",IF(AA37<TODAY(),"Completed","Not Yet")))) -> Not Yet | AD37: =IF(AC37="","Not Yet",IF(AC37=TODAY(),"Today Completed",IF(AC37=TODAY()+1,"Tomorrow's Plan",IF(AC37<TODAY(),"Completed","Not Yet")))) -> Not Yet | AF37: =IF(AE37="","Not Yet",IF(AE37=TODAY(),"Today Completed",IF(AE37=TODAY()+1,"Tomorrow's Plan",IF(AE37<TODAY(),"Completed","Not Yet")))) -> Not Yet | AH37: =IF(AG37="","Not Yet",IF(AG37=TODAY(),"Today Completed",IF(AG37=TODAY()+1,"Tomorrow's Plan",IF(AG37<TODAY(),"Completed","Not Yet")))) -> Not Yet | AJ37: =IF(AI37="","Not Yet",IF(AI37=TODAY(),"Today Completed",IF(AI37=TODAY()+1,"Tomorrow's Plan",IF(AI37<TODAY(),"Completed","Not Yet")))) -> Not Yet | AL37: =IF(AK37="","Not Yet",IF(AK37=TODAY(),"Today Completed",IF(AK37=TODAY()+1,"Tomorrow's Plan",IF(AK37<TODAY(),"Completed","Not Yet")))) -> Not Yet | AM37: 2955 | AN37: 3 | AR37: =VLOOKUP(TOWER_LIST!B37,Spans!B:D,2,) -> 358 | AS37: =VLOOKUP(TOWER_LIST!B37,Spans!B:D,3,) -> 317 | AT37: =ROUND(AS37/AR37,2) -> 0.89 | AY37: 2T-2T | AZ37: 3 | BA37: =IF(AZ37>0,3," ") -> 3 | BC37: 1 | BD37: 1 | BE37: =IF(LEFT(C37,2)="BN","95-S","95-T") -> 95-T | BF37: 1 | BG37: 1 | BH37: =IF(LEFT(BE37,2)="18","JB"," " ) | BI37: =BE37 -> 95-T | BJ37: 1 | BK37: 1 | BL37: 2 | BM37: 0 | BO37: Step-1 | BT37: 10
AQ38: 355 | AU38: 8 | AV38: 355 | AW38: 355 | AX38: =IF(AQ38<700,"400/51","500/204") -> 400/51 | BB38: 7
A39: 12 | B39: 11 | C39: B30+0 | H39: 298787.03 | I39: 4684628 | J39: 114.498 | K39: =IF(O39=TODAY(),"Access Road",IF(Q39=TODAY(),"Soil Investigation",IF(S39=TODAY(),"Excavation",IF(U39=TODAY(),"Lean Concrete",IF(W39=TODAY(),"Stub Settings",IF(Y39=TODAY(),"Concrete",IF(AA39=TODAY(),"Backfilling",IF(AC39=TODAY(),"Ground Erection",IF(AE39=TODAY(),"Crane Erection",IF(AG39=TODAY(),"Conductor",IF(AI39=TODAY(),"EW",IF(AK39=TODAY(),"OPGW","")))))))))))) | L39: =IF(O39=TODAY()+1,"Access Road",IF(Q39=TODAY()+1,"Soil Investigation",IF(S39=TODAY()+1,"Excavation",IF(U39=TODAY()+1,"Lean Concrete",IF(W39=TODAY()+1,"Stub Settings",IF(Y39=TODAY()+1,"Concrete",IF(AA39=TODAY()+1,"Backfilling",IF(AC39=TODAY()+1,"Ground Erection",IF(AE39=TODAY()+1,"Crane Erection",IF(AG39=TODAY()+1,"Conductor",IF(AI39=TODAY()+1,"EW",IF(AK39=TODAY()+1,"OPGW","")))))))))))) | N39: NO PERMISSION / LAND OWNER | O39: 45638 | P39: =IF(O39="","Not Yet",IF(O39=TODAY(),"Today Completed",IF(O39=TODAY()+1,"Tomorrow's Plan",IF(O39<TODAY(),"Completed","Not Yet")))) -> Completed | Q39: 46003 | R39: =IF(Q39="","Not Yet",IF(Q39=TODAY(),"Today Completed",IF(Q39=TODAY()+1,"Tomorrow's Plan",IF(Q39<TODAY(),"Completed","Not Yet")))) -> Completed | T39: =IF(S39="","Not Yet",IF(S39=TODAY(),"Today Completed",IF(S39=TODAY()+1,"Tomorrow's Plan",IF(S39<TODAY(),"Completed","Not Yet")))) -> Not Yet | V39: =IF(U39="","Not Yet",IF(U39=TODAY(),"Today Completed",IF(U39=TODAY()+1,"Tomorrow's Plan",IF(U39<TODAY(),"Completed","Not Yet")))) -> Not Yet | X39: =IF(W39="","Not Yet",IF(W39=TODAY(),"Today Completed",IF(W39=TODAY()+1,"Tomorrow's Plan",IF(W39<TODAY(),"Completed","Not Yet")))) -> Not Yet | Z39: =IF(Y39="","Not Yet",IF(Y39=TODAY(),"Today Completed",IF(Y39=TODAY()+1,"Tomorrow's Plan",IF(Y39<TODAY(),"Completed","Not Yet")))) -> Not Yet | AB39: =IF(AA39="","Not Yet",IF(AA39=TODAY(),"Today Completed",IF(AA39=TODAY()+1,"Tomorrow's Plan",IF(AA39<TODAY(),"Completed","Not Yet")))) -> Not Yet | AD39: =IF(AC39="","Not Yet",IF(AC39=TODAY(),"Today Completed",IF(AC39=TODAY()+1,"Tomorrow's Plan",IF(AC39<TODAY(),"Completed","Not Yet")))) -> Not Yet | AF39: =IF(AE39="","Not Yet",IF(AE39=TODAY(),"Today Completed",IF(AE39=TODAY()+1,"Tomorrow's Plan",IF(AE39<TODAY(),"Completed","Not Yet")))) -> Not Yet | AH39: =IF(AG39="","Not Yet",IF(AG39=TODAY(),"Today Completed",IF(AG39=TODAY()+1,"Tomorrow's Plan",IF(AG39<TODAY(),"Completed","Not Yet")))) -> Not Yet | AJ39: =IF(AI39="","Not Yet",IF(AI39=TODAY(),"Today Completed",IF(AI39=TODAY()+1,"Tomorrow's Plan",IF(AI39<TODAY(),"Completed","Not Yet")))) -> Not Yet | AL39: =IF(AK39="","Not Yet",IF(AK39=TODAY(),"Today Completed",IF(AK39=TODAY()+1,"Tomorrow's Plan",IF(AK39<TODAY(),"Completed","Not Yet")))) -> Not Yet | AM39: 3310 | AN39: 4.1 | AR39: =VLOOKUP(TOWER_LIST!B39,Spans!B:D,2,) -> 345 | AS39: =VLOOKUP(TOWER_LIST!B39,Spans!B:D,3,) -> 350 | AT39: =ROUND(AS39/AR39,2) -> 1.01 | AY39: 2T-2T | AZ39: 3 | BA39: =IF(AZ39>0,3," ") -> 3 | BC39: 1 | BD39: 1 | BE39: =IF(LEFT(C39,2)="BN","95-S","95-T") -> 95-T | BF39: 1 | BG39: 1 | BH39: =IF(LEFT(BE39,2)="18","JB"," " ) | BI39: =BE39 -> 95-T | BJ39: 1 | BK39: 1 | BL39: 2 | BM39: 0 | BO39: Step-1 | BT39: 11
AQ40: 335 | AU40: 9 | AV40: 337.52778 | AW40: 675 | AX40: =IF(AQ40<700,"400/51","500/204") -> 400/51 | BB40: 7 | BR40: ROAD, MV OHDL
A41: 13 | B41: 12 | C41: BNS+3 | H41: 298482.05 | I41: 4684766.6 | J41: 112.108 | K41: =IF(O41=TODAY(),"Access Road",IF(Q41=TODAY(),"Soil Investigation",IF(S41=TODAY(),"Excavation",IF(U41=TODAY(),"Lean Concrete",IF(W41=TODAY(),"Stub Settings",IF(Y41=TODAY(),"Concrete",IF(AA41=TODAY(),"Backfilling",IF(AC41=TODAY(),"Ground Erection",IF(AE41=TODAY(),"Crane Erection",IF(AG41=TODAY(),"Conductor",IF(AI41=TODAY(),"EW",IF(AK41=TODAY(),"OPGW","")))))))))))) | L41: =IF(O41=TODAY()+1,"Access Road",IF(Q41=TODAY()+1,"Soil Investigation",IF(S41=TODAY()+1,"Excavation",IF(U41=TODAY()+1,"Lean Concrete",IF(W41=TODAY()+1,"Stub Settings",IF(Y41=TODAY()+1,"Concrete",IF(AA41=TODAY()+1,"Backfilling",IF(AC41=TODAY()+1,"Ground Erection",IF(AE41=TODAY()+1,"Crane Erection",IF(AG41=TODAY()+1,"Conductor",IF(AI41=TODAY()+1,"EW",IF(AK41=TODAY()+1,"OPGW","")))))))))))) | M41: Active | O41: 45638 | P41: =IF(O41="","Not Yet",IF(O41=TODAY(),"Today Completed",IF(O41=TODAY()+1,"Tomorrow's Plan",IF(O41<TODAY(),"Completed","Not Yet")))) -> Completed | Q41: 46003 | R41: =IF(Q41="","Not Yet",IF(Q41=TODAY(),"Today Completed",IF(Q41=TODAY()+1,"Tomorrow's Plan",IF(Q41<TODAY(),"Completed","Not Yet")))) -> Completed | S41: 46117 | T41: =IF(S41="","Not Yet",IF(S41=TODAY(),"Today Completed",IF(S41=TODAY()+1,"Tomorrow's Plan",IF(S41<TODAY(),"Completed","Not Yet")))) -> Completed | V41: =IF(U41="","Not Yet",IF(U41=TODAY(),"Today Completed",IF(U41=TODAY()+1,"Tomorrow's Plan",IF(U41<TODAY(),"Completed","Not Yet")))) -> Not Yet | X41: =IF(W41="","Not Yet",IF(W41=TODAY(),"Today Completed",IF(W41=TODAY()+1,"Tomorrow's Plan",IF(W41<TODAY(),"Completed","Not Yet")))) -> Not Yet | Z41: =IF(Y41="","Not Yet",IF(Y41=TODAY(),"Today Completed",IF(Y41=TODAY()+1,"Tomorrow's Plan",IF(Y41<TODAY(),"Completed","Not Yet")))) -> Not Yet | AB41: =IF(AA41="","Not Yet",IF(AA41=TODAY(),"Today Completed",IF(AA41=TODAY()+1,"Tomorrow's Plan",IF(AA41<TODAY(),"Completed","Not Yet")))) -> Not Yet | AD41: =IF(AC41="","Not Yet",IF(AC41=TODAY(),"Today Completed",IF(AC41=TODAY()+1,"Tomorrow's Plan",IF(AC41<TODAY(),"Completed","Not Yet")))) -> Not Yet | AF41: =IF(AE41="","Not Yet",IF(AE41=TODAY(),"Today Completed",IF(AE41=TODAY()+1,"Tomorrow's Plan",IF(AE41<TODAY(),"Completed","Not Yet")))) -> Not Yet | AH41: =IF(AG41="","Not Yet",IF(AG41=TODAY(),"Today Completed",IF(AG41=TODAY()+1,"Tomorrow's Plan",IF(AG41<TODAY(),"Completed","Not Yet")))) -> Not Yet | AJ41: =IF(AI41="","Not Yet",IF(AI41=TODAY(),"Today Completed",IF(AI41=TODAY()+1,"Tomorrow's Plan",IF(AI41<TODAY(),"Completed","Not Yet")))) -> Not Yet | AL41: =IF(AK41="","Not Yet",IF(AK41=TODAY(),"Today Completed",IF(AK41=TODAY()+1,"Tomorrow's Plan",IF(AK41<TODAY(),"Completed","Not Yet")))) -> Not Yet | AM41: 3645 | AN41: 4.1 | AR41: =VLOOKUP(TOWER_LIST!B41,Spans!B:D,2,) -> 338 | AS41: =VLOOKUP(TOWER_LIST!B41,Spans!B:D,3,) -> 374 | AT41: =ROUND(AS41/AR41,2) -> 1.11 | AY41: DS | BA41: =IF(AZ41>0,3," ") | BC41: 1 | BD41: 1 | BE41: =IF(LEFT(C41,2)="BN","95-S","95-T") -> 95-S | BF41: 1 | BG41: 1 | BH41: =IF(LEFT(BE41,2)="18","JB"," " ) | BI41: =BE41 -> 95-S | BJ41: 1 | BK41: 1 | BL41: 2 | BM41: 0 | BO41: Step-1 | BT41: 12
AQ42: 340 | AX42: =IF(AQ42<700,"400/51","500/204") -> 400/51 | BB42: 7
A43: 14 | B43: 13 | C43: B30-3 | H43: 298172.52 | I43: 4684907.3 | J43: 108.707 | K43: =IF(O43=TODAY(),"Access Road",IF(Q43=TODAY(),"Soil Investigation",IF(S43=TODAY(),"Excavation",IF(U43=TODAY(),"Lean Concrete",IF(W43=TODAY(),"Stub Settings",IF(Y43=TODAY(),"Concrete",IF(AA43=TODAY(),"Backfilling",IF(AC43=TODAY(),"Ground Erection",IF(AE43=TODAY(),"Crane Erection",IF(AG43=TODAY(),"Conductor",IF(AI43=TODAY(),"EW",IF(AK43=TODAY(),"OPGW","")))))))))))) | L43: =IF(O43=TODAY()+1,"Access Road",IF(Q43=TODAY()+1,"Soil Investigation",IF(S43=TODAY()+1,"Excavation",IF(U43=TODAY()+1,"Lean Concrete",IF(W43=TODAY()+1,"Stub Settings",IF(Y43=TODAY()+1,"Concrete",IF(AA43=TODAY()+1,"Backfilling",IF(AC43=TODAY()+1,"Ground Erection",IF(AE43=TODAY()+1,"Crane Erection",IF(AG43=TODAY()+1,"Conductor",IF(AI43=TODAY()+1,"EW",IF(AK43=TODAY()+1,"OPGW","")))))))))))) | M43: Active | O43: 45638 | P43: =IF(O43="","Not Yet",IF(O43=TODAY(),"Today Completed",IF(O43=TODAY()+1,"Tomorrow's Plan",IF(O43<TODAY(),"Completed","Not Yet")))) -> Completed | Q43: 46003 | R43: =IF(Q43="","Not Yet",IF(Q43=TODAY(),"Today Completed",IF(Q43=TODAY()+1,"Tomorrow's Plan",IF(Q43<TODAY(),"Completed","Not Yet")))) -> Completed | S43: 46116 | T43: =IF(S43="","Not Yet",IF(S43=TODAY(),"Today Completed",IF(S43=TODAY()+1,"Tomorrow's Plan",IF(S43<TODAY(),"Completed","Not Yet")))) -> Completed | U43: 46117 | V43: =IF(U43="","Not Yet",IF(U43=TODAY(),"Today Completed",IF(U43=TODAY()+1,"Tomorrow's Plan",IF(U43<TODAY(),"Completed","Not Yet")))) -> Completed | X43: =IF(W43="","Not Yet",IF(W43=TODAY(),"Today Completed",IF(W43=TODAY()+1,"Tomorrow's Plan",IF(W43<TODAY(),"Completed","Not Yet")))) -> Not Yet | Z43: =IF(Y43="","Not Yet",IF(Y43=TODAY(),"Today Completed",IF(Y43=TODAY()+1,"Tomorrow's Plan",IF(Y43<TODAY(),"Completed","Not Yet")))) -> Not Yet | AB43: =IF(AA43="","Not Yet",IF(AA43=TODAY(),"Today Completed",IF(AA43=TODAY()+1,"Tomorrow's Plan",IF(AA43<TODAY(),"Completed","Not Yet")))) -> Not Yet | AD43: =IF(AC43="","Not Yet",IF(AC43=TODAY(),"Today Completed",IF(AC43=TODAY()+1,"Tomorrow's Plan",IF(AC43<TODAY(),"Completed","Not Yet")))) -> Not Yet | AF43: =IF(AE43="","Not Yet",IF(AE43=TODAY(),"Today Completed",IF(AE43=TODAY()+1,"Tomorrow's Plan",IF(AE43<TODAY(),"Completed","Not Yet")))) -> Not Yet | AH43: =IF(AG43="","Not Yet",IF(AG43=TODAY(),"Today Completed",IF(AG43=TODAY()+1,"Tomorrow's Plan",IF(AG43<TODAY(),"Completed","Not Yet")))) -> Not Yet | AJ43: =IF(AI43="","Not Yet",IF(AI43=TODAY(),"Today Completed",IF(AI43=TODAY()+1,"Tomorrow's Plan",IF(AI43<TODAY(),"Completed","Not Yet")))) -> Not Yet | AL43: =IF(AK43="","Not Yet",IF(AK43=TODAY(),"Today Completed",IF(AK43=TODAY()+1,"Tomorrow's Plan",IF(AK43<TODAY(),"Completed","Not Yet")))) -> Not Yet | AM43: 3985 | AN43: 5.1 | AR43: =VLOOKUP(TOWER_LIST!B43,Spans!B:D,2,) -> 345 | AS43: =VLOOKUP(TOWER_LIST!B43,Spans!B:D,3,) -> 286 | AT43: =ROUND(AS43/AR43,2) -> 0.83 | AY43: 2T-2T | AZ43: 3 | BA43: =IF(AZ43>0,3," ") -> 3 | BC43: 1 | BD43: 1 | BE43: =IF(LEFT(C43,2)="BN","95-S","95-T") -> 95-T | BF43: 1 | BG43: 1 | BH43: =IF(LEFT(BE43,2)="18","JB"," " ) | BI43: =BE43 -> 95-T | BJ43: 1 | BK43: 1 | BL43: 2 | BM43: 0 | BO43: Step-1 | BT43: 13
...

Sheet Summary
A1: Contractor: | J1: Customer: | K1: Consultant:
K2: STRUCTURE LIST
A7: LOT 1: CONSTRUCTION OF 500KV JVARI - TSKALTUBO OVERHEAD LINE
A9: SUMMARY LIST
D12: FOUNDATIONS
B13: Towers | C13: Total | D13: Good Soil | E13: Poor Soil | F13: Soft Rock | G13: Hard Rock | H13: Water Logged | J13: LINE'S TOTAL LENGTH (m): | K13: =TOWER_LIST!AM417 -> 76074.23
D14: FDN1 | E14: FDN2 | F14: FDN3 | G14: FDN4 | H14: FDN5 | J14: TOTAL LINE LENGTH WITH ACO 400/51 CONDUCTOR (m): | K14: =SUMIF(TOWER_LIST!AX18:AX417,"400/51",TOWER_LIST!AQ18:AQ417) -> 69010.953
B15: BNS-6 | C15: =COUNTIF(TOWER_LIST!$C$2:$C$228,Summary!B15) -> 0 | D15: =C15 -> 0 | J15: TOTAL LINE LENGTH WITH ACYC 500/204 CONDUCTOR (m): | K15: =SUMIF(TOWER_LIST!AX18:AX417,"500/204",TOWER_LIST!AQ18:AQ417) -> 8530.515
B16: BNS-3 | C16: =COUNTIF(TOWER_LIST!$C$2:$C$1101,Summary!B16) -> 8 | D16: =C16 -> 8
B17: BNS+0 | C17: =COUNTIF(TOWER_LIST!$C$2:$C$1101,Summary!B17) -> 4 | D17: =C17 -> 4 | J17: PHASE CONDUCTOR
B18: BNS+3 | C18: =COUNTIF(TOWER_LIST!$C$2:$C$1101,Summary!B18) -> 16 | D18: =C18 -> 16 | J18: Insulator Strings Sets
B19: BNS+6 | C19: =COUNTIF(TOWER_LIST!$C$2:$C$1101,Summary!B19) -> 12 | D19: =C19 -> 12
B20: BNS+9 | C20: =COUNTIF(TOWER_LIST!$C$2:$C$1101,Summary!B20) -> 8 | D20: =C20 -> 8 | J20: Type | K20: Code | L20: Set/ Phase | M20: SC | N20: Total Sets
B21: BNS+12 | C21: =COUNTIF(TOWER_LIST!$C$2:$C$1101,Summary!B21) -> 6 | D21: =C21 -> 6
J22: SINGLE SUSPENSION SET (ACO 400/51) | K22: SS | L22: =COUNTIF(TOWER_LIST!AY17:AY550,Summary!K22) -> 43 | M22: 3 | N22: =L22*M22 -> 129
J23: DOUBLE SUSPENSION SET (ACO 400/51) | K23: DS | L23: =COUNTIF(TOWER_LIST!AY18:AY551,Summary!K23) -> 11 | M23: 3 | N23: =L23*M23 -> 33
B24: BLC-6 | C24: =COUNTIF(TOWER_LIST!$C$2:$C$1101,Summary!B24) -> 2 | D24: =C24 -> 2 | J24: DOUBLE TENSION (ACO 400/51) | K24: 2T | L24: =COUNTIF(TOWER_LIST!AY17:AY1698,"2T-2T")*2+COUNTIF(TOWER_LIST!AY17:AY1698,"3T-2T")+COUNTIF(TOWER_LIST!AY17:AY1698,"2T-3T")+COUNTIF(TOWER_LIST!AY17:AY1698,"2T") -> 270 | M24: 3 | N24: =L24*M24 -> 810
B25: BLC+0 | C25: =COUNTIF(TOWER_LIST!$C$2:$C$1101,Summary!B25) -> 3 | D25: =C25 -> 3 | J25: TRIPLE TENSION SET (ACYC 500/204) | K25: 3T | L25: =COUNTIF(TOWER_LIST!AY17:AY1698,"3T-3T")*2+COUNTIF(TOWER_LIST!AY17:AY1698,"3T-2T")+COUNTIF(TOWER_LIST!AY17:AY1698,"2T-3T") -> 22 | M25: 3 | N25: =L25*M25 -> 66
B26: BLC+6 | C26: =COUNTIF(TOWER_LIST!$C$2:$C$1101,Summary!B26) -> 0 | D26: =C26 -> 0 | J26: JUMPER SUSPENSION SET (ACO 400/51) | K26: JS | L26: =SUM(TOWER_LIST!AZ17:AZ417) -> 358 | M26: 1 | N26: =L26*M26 -> 358
B27: BLC+12 | C27: =COUNTIF(TOWER_LIST!$C$2:$C$1101,Summary!B27) -> 1 | D27: =C27 -> 1 | J27: Type | K27: Code | L27: Set/ Phase | M27: SC | N27: Total Sets / Units
B28: BLC+18 | C28: =COUNTIF(TOWER_LIST!$C$2:$C$1101,Summary!B28) -> 4 | D28: =C28 -> 4
B29: BLS-6 | C29: =COUNTIF(TOWER_LIST!$C$2:$C$1101,Summary!B29) -> 8 | D29: =C29 -> 8 | J29: 210 kN SILICONE SUSPENSION INSULATORS | L29: =N22+N23*2 -> 195
B30: BLS+0 | C30: =COUNTIF(TOWER_LIST!$C$2:$C$1101,Summary!B30) -> 7 | D30: =C30 -> 7 | J30: 210 kN SILICONE INSULATORS FOR DOUBLE TENSION SET | L30: =N24*2 -> 1620
B31: BLS+6 | C31: =COUNTIF(TOWER_LIST!$C$2:$C$1101,Summary!B31) -> 4 | D31: =C31 -> 4 | J31: 320 kN SILICONE INSULATORS FOR TRIPLE TENSION SET | L31: =N25*3 -> 198
B32: BLS+12 | C32: =COUNTIF(TOWER_LIST!$C$2:$C$1101,Summary!B32) -> 2 | D32: =C32 -> 2 | J32: 210 kN JUMPER SUSPENSION INSULATORS | L32: =N26 -> 358
B33: BLS+18 | C33: =COUNTIF(TOWER_LIST!$C$2:$C$1101,Summary!B33) -> 3 | D33: =C33 -> 3 | J33: RIGID SPACER | L33: =SUMPRODUCT(TOWER_LIST!AZ17:AZ418,TOWER_LIST!BA17:BA418) -> 780
B34: B30-6 | C34: =COUNTIF(TOWER_LIST!$C$2:$C$1101,Summary!B34) -> 0 | D34: =C34 -> 0 | J34: SPACER DAMPER FOR ACO 400/51 | L34: =SUMIF(TOWER_LIST!AX18:AX417,"400/51",TOWER_LIST!BB18:BB417) -> 1045 | M34: 3 | N34: =L34*M34 -> 3135
B35: B30-3 | C35: =COUNTIF(TOWER_LIST!$C$2:$C$1101,Summary!B35) -> 39 | D35: =C35 -> 39 | J35: SPACER DAMPER FOR ACYC 500/204 | L35: =SUMIF(TOWER_LIST!AX17:AX416,"500/204",TOWER_LIST!BB17:BB416) -> 131 | M35: 3 | N35: =L35*M35 -> 393
B36: B30+0 | C36: =COUNTIF(TOWER_LIST!$C$2:$C$1101,Summary!B36) -> 12 | D36: =C36 -> 12 | J36: STOCKBRIDGE DAMPER FOR ACO 400/51 | K36: UT3 | L36: =SUM(TOWER_LIST!BC16:BD417)-L37 -> 420 | M36: 3 | N36: =L36*M36*3 -> 3780
B37: B30+3 | C37: =COUNTIF(TOWER_LIST!$C$2:$C$1101,Summary!B37) -> 13 | D37: =C37 -> 13 | J37: STOCKBRIDGE DAMPER FOR ACYC 500/204 | K37: UT3 | L37: =40 -> 40 | M37: 3 | N37: =L37*M37*3 -> 360
B38: B30+6 | C38: =COUNTIF(TOWER_LIST!$C$2:$C$1101,Summary!B38) -> 7 | D38: =C38 -> 7 | J38: COUNTER WEIGHT (50kg) | L38: 10 | M38: 3 | N38: =L38*M38 -> 30
B39: B30+9 | C39: =COUNTIF(TOWER_LIST!$C$2:$C$1101,Summary!B39) -> 4 | D39: =C39 -> 4
B40: B30+12 | C40: =COUNTIF(TOWER_LIST!$C$2:$C$1101,Summary!B40) -> 13 | D40: =C40 -> 13 | J40: OPGW
B41: B60-6 | C41: =COUNTIF(TOWER_LIST!$C$2:$C$1101,Summary!B41) -> 0 | D41: =C41 -> 0 | J41: Type | M41: Code | N41: Total
B42: B60-3 | C42: =COUNTIF(TOWER_LIST!$C$2:$C$1101,Summary!B42) -> 6 | D42: =C42 -> 6 | J42: SUSPENSION SET (95 TYPE - 24 FIBERS) | M42: 95-S | N42: =COUNTIF(TOWER_LIST!BE17:BE418,M42) -> 54
B43: B60S-3 | C43: =COUNTIF(TOWER_LIST!$C$2:$C$1101,Summary!B43) -> 0 | D43: =C43 -> 0 | J43: TENSION NON-JOINT SET (95 TYPE - 24 FIBERS) | M43: 95-T | N43: 115
B44: B60+0 | C44: =COUNTIF(TOWER_LIST!$C$2:$C$1101,Summary!B44) -> 1 | D44: =C44 -> 1 | J44: TENSION JOINT SET DOUBLE (95 TYPE - 24 FIBERS) | M44: 95-T | N44: 18
B45: B60+3 | C45: =COUNTIF(TOWER_LIST!$C$2:$C$1101,Summary!B45) -> 2 | D45: =C45 -> 2 | J45: TENSION JOINT SET SINGLE (95 TYPE - 24 FIBERS) | M45: 95-TSJ | N45: 2
B46: B60+6 | C46: =COUNTIF(TOWER_LIST!$C$2:$C$1101,Summary!B46) -> 2 | D46: =C46 -> 2 | J46: TENSION JOINT SET DOUBLE (185 TYPE - 24 FIBERS) | M46: 185-T | N46: 7
B47: B60+9 | C47: =COUNTIF(TOWER_LIST!$C$2:$C$1101,Summary!B47) -> 1 | D47: =C47 -> 1 | J47: STOCKBRIDGE DAMPER FOR (95 TYPE - 24 FIBERS) | M47: UT2 | N47: =SUM(TOWER_LIST!BF16:BG417)-N48 -> 416
...

Sheet Spans
B1: No. | C1: Wind Span | D1: Weight Span
B2: G1 | C2: 43 | D2: 53
B3: 1 | C3: 183 | D3: 224
B4: 2 | C4: 280 | D4: 250
B5: 3 | C5: 291 | D5: 353
B6: 4 | C6: 302 | D6: 234
B7: 5 | C7: 321 | D7: 361
B8: 6 | C8: 274 | D8: 249
B9: 7 | C9: 308 | D9: 343
B10: 8 | C10: 398 | D10: 378
B11: 9 | C11: 375 | D11: 414
B12: 10 | C12: 358 | D12: 317
B13: 11 | C13: 345 | D13: 350
B14: 12 | C14: 338 | D14: 374
... B205: 205 | C205: 247 | D205: 270
B206: G2 | C206: 41 | D206: 39
